Workbook

Sheet 표
B1: 아이템 확인용(2024.12.15.) | S1: 재료(이름,가격), 아이템(이름, 조합법, 지식의 기억) 수정 가능 구역
B3: 아이템 종류 순서대로 정렬 | G3: 종류 별 합계 | J3: 가격 순서대로 정렬 | O3: 아이템 합계 | S3: 재료 아이템 | X3: 완성 아이템 추가 및 조합법 수정하는 곳
B4: 완성 아이템 | C4: 조합법 | D4: 지식의 기억 | E4: 가격 | G4: 총합 | H4: =SUM(H5:H9) -> 26 | J4: 완성 아이템 | K4: 조합법 | L4: 지식의 기억 | M4: 가격 | O4: 재료+아이템 | P4: =COUNTA(S5:S90)+COUNTA(U5:U171)+P5 -> 42 | S4: 기본 재료(16개) | T4: 가격 | U4: 고급 재료 | V4: 가격 | X4: 완성 아이템 | Y4: 조합법 | Z4: 지식의 기억 | AA4: 가격
B5: {=_xlfn._xlws.SORT(X5:AA40,1)} -> 1. 강화 신발 | C5: +천+전기부품+철 | D5: 강화 신발의 기억 | E5: 208 | G5: {=_xlfn._xlws.SORT(Sheet2!AW6:AX10,2,-1)} -> 2. 도구 | H5: 8 | J5: {=_xlfn._xlws.SORT(X5:AA40,4)} -> 3. 방망이 | K5: +나무+나무 | L5: 0 | M5: 32 | O5: 아이템 | P5: =COUNTA(X5:X103) -> 26 | S5: 나무 | T5: 16 | U5: 실 | V5: 64 | X5: 1. 옷 | Y5: +천 | AA5: =Sheet2!F1 -> 80
B6: 1. 옷 | C6: +천 | D6: 0 | E6: 80 | G6: 3. 공격 | H6: 5 | J6: 4. 보관함 | K6: +나무+나무+철 | L6: 0 | M6: 64 | O6: 지식의 기억 | P6: =COUNTA(Z5:Z323) -> 12 | S6: 단 열매 | T6: 16 | U6: 천 | V6: 80 | X6: 1. 좋은 손전등 | Y6: +전기부품+철+황동 | Z6: 좋은손전등의 기억 | AA6: =Sheet2!K1 -> 192
B7: 1. 점프팩 | C7: +천+전기부품+황동 | D7: 점프팩 | E7: 240 | G7: 5. 설치 | H7: 5 | J7: 5. 초급 포션 | K7: +단 열매+쓴 열매+철 | L7: 0 | M7: 64 | O7: 재료 | P7: =P4-P5 -> 16 | S7: 쓴 열매 | T7: 16 | U7: 전기부품 | V7: 96 | X7: 1. 강화 신발 | Y7: +천+전기부품+철 | Z7: 강화 신발의 기억 | AA7: =Sheet2!P1 -> 208
B8: 1. 좋은 손전등 | C8: +전기부품+철+황동 | D8: 좋은손전등의 기억 | E8: 192 | G8: 1. 장비 | H8: 4 | J8: 1. 옷 | K8: +천 | L8: 0 | M8: 80 | S8: 작은 물고기 | T8: 16 | U8: 산삼 | V8: 100 | X8: 1. 점프팩 | Y8: +천+전기부품+황동 | Z8: 점프팩 | AA8: =Sheet2!U1 -> 240
B9: 2. 곡괭이 | C9: +실+나무+황동 | D9: 0 | E9: 144 | G9: 4. 섭취 | H9: 4 | J9: 2. 열쇠 | K9: +나무+황동 | L9: 0 | M9: 80 | S9: 큰 물고기 | T9: 32 | U9: 다이아몬드 | V9: 100 | X9: 2. 도끼 | Y9: +실+나무+철 | Z9: 점프팩 | AA9: =Sheet2!Z1 -> 112
B10: 2. 귀환석 | C10: +마법석+황동+화약 | D10: 귀환석의 기억 | E10: 272 | J10: 5. 중급 포션 | K10: +단 열매+쓴 열매+작은 물고기+큰 물고기 | L10: 0 | M10: 80 | S10: 철 | T10: 32 | U10: 상어 | V10: 100 | X10: 2. 곡괭이 | Y10: +실+나무+황동 | AA10: =Sheet2!AE1 -> 144
B11: 2. 낚시대 | C11: +실+나무+철 | D11: 0 | E11: 112 | J11: 5. 기력 회복 포션 | K11: +작은 물고기+큰 물고기+철 | L11: 0 | M11: 80 | S11: 황동 | T11: 64 | U11: 마법석 | V11: 128 | X11: 2. 낚시대 | Y11: +실+나무+철 | AA11: =Sheet2!AJ1 -> 112
B12: 2. 도끼 | C12: +실+나무+철 | D12: 점프팩 | E12: 112 | J12: 2. 횟불 | K12: +나무+화약 | L12: 0 | M12: 96 | S12: 화약 | T12: 80 | U12: 총기부품 | V12: 144 | X12: 2. 열쇠 | Y12: +나무+황동 | AA12: =Sheet2!F13 -> 80
B13: 2. 만능키 | C13: +마법석+나무+황동 | D13: 만능키의 기억 | E13: 208 | J13: 3. 소드 | K13: +나무+나무+철+철 | L13: 소드의 기억 | M13: 96 | X13: 2. 만능키 | Y13: +마법석+나무+황동 | Z13: 만능키의 기억 | AA13: =Sheet2!K13 -> 208
B14: 2. 열쇠 | C14: +나무+황동 | D14: 0 | E14: 80 | J14: 2. 도끼 | K14: +실+나무+철 | L14: 점프팩 | M14: 112 | X14: 2. 횟불 | Y14: +나무+화약 | AA14: =Sheet2!P13 -> 96
B15: 2. 총+총알 | C15: +총+총알 | D15: 0 | E15: 368 | J15: 2. 낚시대 | K15: +실+나무+철 | L15: 0 | M15: 112 | X15: 2. 귀환석 | Y15: +마법석+황동+화약 | Z15: 귀환석의 기억 | AA15: =Sheet2!U13 -> 272
B16: 2. 횟불 | C16: +나무+화약 | D16: 0 | E16: 96 | J16: 4. 가구 | K16: +나무+나무+천 | L16: 가구의 기억 | M16: 112 | X16: 3. 방망이 | Y16: +나무+나무 | AA16: =Sheet2!Z13 -> 32
B17: 3. 망치 | C17: +나무+철+철+다이아몬드+천 | D17: 망치의 기억 | E17: 260 | J17: 5. 고급 포션 | K17: 단 열매+쓴 열매+산삼 | L17: 포션의 기억 | M17: 116 | X17: 3. 소드 | Y17: +나무+나무+철+철 | Z17: 소드의 기억 | AA17: =Sheet2!AE13 -> 96
B18: 3. 방망이 | C18: +나무+나무 | D18: 0 | E18: 32 | J18: 2. 곡괭이 | K18: +실+나무+황동 | L18: 0 | M18: 144 | X18: 3. 망치 | Y18: +나무+철+철+다이아몬드+천 | Z18: 망치의 기억 | AA18: =Sheet2!AJ13 -> 260
B19: 3. 소드 | C19: +나무+나무+철+철 | D19: 소드의 기억 | E19: 96 | J19: 4. 울타리 | K19: +나무+나무+나무+철+황동 | L19: 0 | M19: 144 | X19: 3. 총 | Y19: +총기부품+나무+철 | Z19: 총의 기억 | AA19: =Sheet2!F25 -> 192
B20: 3. 총 | C20: +총기부품+나무+철 | D20: 총의 기억 | E20: 192 | J20: 4. 표지판 | K20: +나무+나무+철+천 | L20: 표지판의 기억 | M20: 144 | X20: 3. 총알 | Y20: +철+황동+화약 | AA20: =Sheet2!K25 -> 176
B21: 3. 총알 | C21: +철+황동+화약 | D21: 0 | E21: 176 | J21: 5. 아드레날린 | K21: +상어+단 열매+철 | L21: 0 | M21: 148 | X21: 4. 보관함 | Y21: +나무+나무+철 | AA21: =Sheet2!P25 -> 64
B22: 4. 가구 | C22: +나무+나무+천 | D22: 가구의 기억 | E22: 112 | J22: 3. 총알 | K22: +철+황동+화약 | L22: 0 | M22: 176 | X22: 4. 울타리 | Y22: +나무+나무+나무+철+황동 | AA22: =Sheet2!U25 -> 144
B23: 4. 보관함 | C23: +나무+나무+철 | D23: 0 | E23: 64 | J23: 1. 좋은 손전등 | K23: +전기부품+철+황동 | L23: 좋은손전등의 기억 | M23: 192 | X23: 4. 표지판 | Y23: +나무+나무+철+천 | Z23: 표지판의 기억 | AA23: =Sheet2!Z25 -> 144
B24: 4. 울타리 | C24: +나무+나무+나무+철+황동 | D24: 0 | E24: 144 | J24: 3. 총 | K24: +총기부품+나무+철 | L24: 총의 기억 | M24: 192 | X24: 4. 가구 | Y24: +나무+나무+천 | Z24: 가구의 기억 | AA24: =Sheet2!AE25 -> 112
B25: 4. 표지판 | C25: +나무+나무+철+천 | D25: 표지판의 기억 | E25: 144 | J25: 1. 강화 신발 | K25: +천+전기부품+철 | L25: 강화 신발의 기억 | M25: 208 | X25: 5. 초급 포션 | Y25: +단 열매+쓴 열매+철 | AA25: =Sheet2!AJ25 -> 64
B26: 5. 고급 포션 | C26: 단 열매+쓴 열매+산삼 | D26: 포션의 기억 | E26: 116 | J26: 2. 만능키 | K26: +마법석+나무+황동 | L26: 만능키의 기억 | M26: 208 | X26: 2. 총+총알 | Y26: +총+총알 | AA26: =SUM(AA19:AA20) -> 368
B27: 5. 기력 회복 포션 | C27: +작은 물고기+큰 물고기+철 | D27: 0 | E27: 80 | J27: 1. 점프팩 | K27: +천+전기부품+황동 | L27: 점프팩 | M27: 240 | X27: 5. 중급 포션 | Y27: +단 열매+쓴 열매+작은 물고기+큰 물고기 | AA27: =Sheet2!F37 -> 80
B28: 5. 아드레날린 | C28: +상어+단 열매+철 | D28: 0 | E28: 148 | J28: 3. 망치 | K28: +나무+철+철+다이아몬드+천 | L28: 망치의 기억 | M28: 260 | X28: 5. 고급 포션 | Y28: 단 열매+쓴 열매+산삼 | Z28: 포션의 기억 | AA28: =Sheet2!K37 -> 116
B29: 5. 중급 포션 | C29: +단 열매+쓴 열매+작은 물고기+큰 물고기 | D29: 0 | E29: 80 | J29: 2. 귀환석 | K29: +마법석+황동+화약 | L29: 귀환석의 기억 | M29: 272 | X29: 5. 기력 회복 포션 | Y29: +작은 물고기+큰 물고기+철 | AA29: =Sheet2!P37 -> 80
B30: 5. 초급 포션 | C30: +단 열매+쓴 열매+철 | D30: 0 | E30: 64 | J30: 2. 총+총알 | K30: +총+총알 | L30: 0 | M30: 368 | X30: 5. 아드레날린 | Y30: +상어+단 열매+철 | AA30: =Sheet2!U37 -> 148
B31: 0 | C31: 0 | D31: 0 | E31: #N/A | J31: 0 | K31: 0 | L31: 0 | M31: #N/A | AA31: =Sheet2!Z37 -> #N/A
B32: 0 | C32: 0 | D32: 0 | E32: #N/A | J32: 0 | K32: 0 | L32: 0 | M32: #N/A | AA32: =Sheet2!AE37 -> #N/A
B33: 0 | C33: 0 | D33: 0 | E33: #N/A | J33: 0 | K33: 0 | L33: 0 | M33: #N/A | AA33: =Sheet2!AJ37 -> #N/A
B34: 0 | C34: 0 | D34: 0 | E34: #N/A | J34: 0 | K34: 0 | L34: 0 | M34: #N/A | AA34: =Sheet2!F49 -> #N/A
B35: 0 | C35: 0 | D35: 0 | E35: #N/A | J35: 0 | K35: 0 | L35: 0 | M35: #N/A | AA35: =Sheet2!K49 -> #N/A
B36: 0 | C36: 0 | D36: 0 | E36: #N/A | J36: 0 | K36: 0 | L36: 0 | M36: #N/A | AA36: =Sheet2!P49 -> #N/A
B37: 0 | C37: 0 | D37: 0 | E37: #N/A | J37: 0 | K37: 0 | L37: 0 | M37: #N/A | AA37: =Sheet2!U49 -> #N/A
B38: 0 | C38: 0 | D38: 0 | E38: #N/A | J38: 0 | K38: 0 | L38: 0 | M38: #N/A | AA38: =Sheet2!Z49 -> #N/A
B39: 0 | C39: 0 | D39: 0 | E39: #N/A | J39: 0 | K39: 0 | L39: 0 | M39: #N/A | AA39: =Sheet2!AE49 -> #N/A
B40: 0 | C40: 0 | D40: 0 | E40: #N/A | J40: 0 | K40: 0 | L40: 0 | M40: #N/A | AA40: =Sheet2!AJ49 -> #N/A

Sheet Sheet2
A1: =표!S5 -> 나무 | B1: =표!T5 -> 16 | C1: =표!Y5 -> +천 | D1: =TRIM(MID(SUBSTITUTE($C$1,"+",REPT(" ",LEN($C$1))),(ROW()-ROW($D$1)+1)*LEN($C$1),LEN($C$1))) -> 천 | E1: =IF(D1<>"",VLOOKUP(D1,$A$1:$B$130,2,FALSE),0) -> 80 | F1: =SUM(E1:E10) -> 80 | H1: =표!Y6 -> +전기부품+철+황동 | I1: =TRIM(MID(SUBSTITUTE($H$1,"+",REPT(" ",LEN($H$1))),(ROW()-ROW($I$1)+1)*LEN($H$1),LEN($H$1))) -> 전기부품 | J1: =IF(I1<>"",VLOOKUP(I1,$A$1:$B$130,2,FALSE),0) -> 96 | K1: =SUM(J1:J10) -> 192 | M1: =표!Y7 -> +천+전기부품+철 | N1: =TRIM(MID(SUBSTITUTE($M$1,"+",REPT(" ",LEN($M$1))),(ROW()-ROW($N$1)+1)*LEN($M$1),LEN($M$1))) -> 천 | O1: =IF(N1<>"",VLOOKUP(N1,$A$1:$B$130,2,FALSE),0) -> 80 | P1: =SUM(O1:O10) -> 208 | R1: =표!Y8 -> +천+전기부품+황동 | S1: =TRIM(MID(SUBSTITUTE($R$1,"+",REPT(" ",LEN($R$1))),(ROW()-ROW($S$1)+1)*LEN($R$1),LEN($R$1))) -> 천 | T1: =IF(S1<>"",VLOOKUP(S1,$A$1:$B$130,2,FALSE),0) -> 80 | U1: =SUM(T1:T10) -> 240 | W1: =표!Y9 -> +실+나무+철 | X1: =TRIM(MID(SUBSTITUTE($W$1,"+",REPT(" ",LEN($W$1))),(ROW()-ROW($X$1)+1)*LEN($W$1),LEN($W$1))) -> 실 | Y1: =IF(X1<>"",VLOOKUP(X1,$A$1:$B$130,2,FALSE),0) -> 64 | Z1: =SUM(Y1:Y10) -> 112 | AB1: =표!Y10 -> +실+나무+황동 | AC1: =TRIM(MID(SUBSTITUTE($AB$1,"+",REPT(" ",LEN($AB$1))),(ROW()-ROW($AC$1)+1)*LEN($AB$1),LEN($AB$1))) -> 실 | AD1: =IF(AC1<>"",VLOOKUP(AC1,$A$1:$B$130,2,FALSE),0) -> 64 | AE1: =SUM(AD1:AD10) -> 144 | AG1: =표!Y11 -> +실+나무+철 | AH1: =TRIM(MID(SUBSTITUTE($AG$1,"+",REPT(" ",LEN($AG$1))),(ROW()-ROW($AH$1)+1)*LEN($AG$1),LEN($AG$1))) -> 실 | AI1: =IF(AH1<>"",VLOOKUP(AH1,$A$1:$B$130,2,FALSE),0) -> 64 | AJ1: =SUM(AI1:AI10) -> 112
A2: =표!S6 -> 단 열매 | B2: =표!T6 -> 16 | D2: =TRIM(MID(SUBSTITUTE($C$1,"+",REPT(" ",LEN($C$1))),(ROW()-ROW($D$1)+1)*LEN($C$1),LEN($C$1))) | E2: =IF(D2<>"",VLOOKUP(D2,$A$1:$B$130,2,FALSE),0) -> 0 | I2: =TRIM(MID(SUBSTITUTE($H$1,"+",REPT(" ",LEN($H$1))),(ROW()-ROW($I$1)+1)*LEN($H$1),LEN($H$1))) -> 철 | J2: =IF(I2<>"",VLOOKUP(I2,$A$1:$B$130,2,FALSE),0) -> 32 | N2: =TRIM(MID(SUBSTITUTE($M$1,"+",REPT(" ",LEN($M$1))),(ROW()-ROW($N$1)+1)*LEN($M$1),LEN($M$1))) -> 전기부품 | O2: =IF(N2<>"",VLOOKUP(N2,$A$1:$B$130,2,FALSE),0) -> 96 | S2: =TRIM(MID(SUBSTITUTE($R$1,"+",REPT(" ",LEN($R$1))),(ROW()-ROW($S$1)+1)*LEN($R$1),LEN($R$1))) -> 전기부품 | T2: =IF(S2<>"",VLOOKUP(S2,$A$1:$B$130,2,FALSE),0) -> 96 | X2: =TRIM(MID(SUBSTITUTE($W$1,"+",REPT(" ",LEN($W$1))),(ROW()-ROW($X$1)+1)*LEN($W$1),LEN($W$1))) -> 나무 | Y2: =IF(X2<>"",VLOOKUP(X2,$A$1:$B$130,2,FALSE),0) -> 16 | AC2: =TRIM(MID(SUBSTITUTE($AB$1,"+",REPT(" ",LEN($AB$1))),(ROW()-ROW($AC$1)+1)*LEN($AB$1),LEN($AB$1))) -> 나무 | AD2: =IF(AC2<>"",VLOOKUP(AC2,$A$1:$B$130,2,FALSE),0) -> 16 | AH2: =TRIM(MID(SUBSTITUTE($AG$1,"+",REPT(" ",LEN($AG$1))),(ROW()-ROW($AH$1)+1)*LEN($AG$1),LEN($AG$1))) -> 나무 | AI2: =IF(AH2<>"",VLOOKUP(AH2,$A$1:$B$130,2,FALSE),0) -> 16
A3: =표!S7 -> 쓴 열매 | B3: =표!T7 -> 16 | D3: =TRIM(MID(SUBSTITUTE($C$1,"+",REPT(" ",LEN($C$1))),(ROW()-ROW($D$1)+1)*LEN($C$1),LEN($C$1))) | E3: =IF(D3<>"",VLOOKUP(D3,$A$1:$B$130,2,FALSE),0) -> 0 | I3: =TRIM(MID(SUBSTITUTE($H$1,"+",REPT(" ",LEN($H$1))),(ROW()-ROW($I$1)+1)*LEN($H$1),LEN($H$1))) -> 황동 | J3: =IF(I3<>"",VLOOKUP(I3,$A$1:$B$130,2,FALSE),0) -> 64 | N3: =TRIM(MID(SUBSTITUTE($M$1,"+",REPT(" ",LEN($M$1))),(ROW()-ROW($N$1)+1)*LEN($M$1),LEN($M$1))) -> 철 | O3: =IF(N3<>"",VLOOKUP(N3,$A$1:$B$130,2,FALSE),0) -> 32 | S3: =TRIM(MID(SUBSTITUTE($R$1,"+",REPT(" ",LEN($R$1))),(ROW()-ROW($S$1)+1)*LEN($R$1),LEN($R$1))) -> 황동 | T3: =IF(S3<>"",VLOOKUP(S3,$A$1:$B$130,2,FALSE),0) -> 64 | X3: =TRIM(MID(SUBSTITUTE($W$1,"+",REPT(" ",LEN($W$1))),(ROW()-ROW($X$1)+1)*LEN($W$1),LEN($W$1))) -> 철 | Y3: =IF(X3<>"",VLOOKUP(X3,$A$1:$B$130,2,FALSE),0) -> 32 | AC3: =TRIM(MID(SUBSTITUTE($AB$1,"+",REPT(" ",LEN($AB$1))),(ROW()-ROW($AC$1)+1)*LEN($AB$1),LEN($AB$1))) -> 황동 | AD3: =IF(AC3<>"",VLOOKUP(AC3,$A$1:$B$130,2,FALSE),0) -> 64 | AH3: =TRIM(MID(SUBSTITUTE($AG$1,"+",REPT(" ",LEN($AG$1))),(ROW()-ROW($AH$1)+1)*LEN($AG$1),LEN($AG$1))) -> 철 | AI3: =IF(AH3<>"",VLOOKUP(AH3,$A$1:$B$130,2,FALSE),0) -> 32
A4: =표!S8 -> 작은 물고기 | B4: =표!T8 -> 16 | D4: =TRIM(MID(SUBSTITUTE($C$1,"+",REPT(" ",LEN($C$1))),(ROW()-ROW($D$1)+1)*LEN($C$1),LEN($C$1))) | E4: =IF(D4<>"",VLOOKUP(D4,$A$1:$B$130,2,FALSE),0) -> 0 | I4: =TRIM(MID(SUBSTITUTE($H$1,"+",REPT(" ",LEN($H$1))),(ROW()-ROW($I$1)+1)*LEN($H$1),LEN($H$1))) | J4: =IF(I4<>"",VLOOKUP(I4,$A$1:$B$130,2,FALSE),0) -> 0 | N4: =TRIM(MID(SUBSTITUTE($M$1,"+",REPT(" ",LEN($M$1))),(ROW()-ROW($N$1)+1)*LEN($M$1),LEN($M$1))) | O4: =IF(N4<>"",VLOOKUP(N4,$A$1:$B$130,2,FALSE),0) -> 0 | S4: =TRIM(MID(SUBSTITUTE($R$1,"+",REPT(" ",LEN($R$1))),(ROW()-ROW($S$1)+1)*LEN($R$1),LEN($R$1))) | T4: =IF(S4<>"",VLOOKUP(S4,$A$1:$B$130,2,FALSE),0) -> 0 | X4: =TRIM(MID(SUBSTITUTE($W$1,"+",REPT(" ",LEN($W$1))),(ROW()-ROW($X$1)+1)*LEN($W$1),LEN($W$1))) | Y4: =IF(X4<>"",VLOOKUP(X4,$A$1:$B$130,2,FALSE),0) -> 0 | AC4: =TRIM(MID(SUBSTITUTE($AB$1,"+",REPT(" ",LEN($AB$1))),(ROW()-ROW($AC$1)+1)*LEN($AB$1),LEN($AB$1))) | AD4: =IF(AC4<>"",VLOOKUP(AC4,$A$1:$B$130,2,FALSE),0) -> 0 | AH4: =TRIM(MID(SUBSTITUTE($AG$1,"+",REPT(" ",LEN($AG$1))),(ROW()-ROW($AH$1)+1)*LEN($AG$1),LEN($AG$1))) | AI4: =IF(AH4<>"",VLOOKUP(AH4,$A$1:$B$130,2,FALSE),0) -> 0
A5: =표!U5 -> 실 | B5: =표!V5 -> 64 | D5: =TRIM(MID(SUBSTITUTE($C$1,"+",REPT(" ",LEN($C$1))),(ROW()-ROW($D$1)+1)*LEN($C$1),LEN($C$1))) | E5: =IF(D5<>"",VLOOKUP(D5,$A$1:$B$130,2,FALSE),0) -> 0 | I5: =TRIM(MID(SUBSTITUTE($H$1,"+",REPT(" ",LEN($H$1))),(ROW()-ROW($I$1)+1)*LEN($H$1),LEN($H$1))) | J5: =IF(I5<>"",VLOOKUP(I5,$A$1:$B$130,2,FALSE),0) -> 0 | N5: =TRIM(MID(SUBSTITUTE($M$1,"+",REPT(" ",LEN($M$1))),(ROW()-ROW($N$1)+1)*LEN($M$1),LEN($M$1))) | O5: =IF(N5<>"",VLOOKUP(N5,$A$1:$B$130,2,FALSE),0) -> 0 | S5: =TRIM(MID(SUBSTITUTE($R$1,"+",REPT(" ",LEN($R$1))),(ROW()-ROW($S$1)+1)*LEN($R$1),LEN($R$1))) | T5: =IF(S5<>"",VLOOKUP(S5,$A$1:$B$130,2,FALSE),0) -> 0 | X5: =TRIM(MID(SUBSTITUTE($W$1,"+",REPT(" ",LEN($W$1))),(ROW()-ROW($X$1)+1)*LEN($W$1),LEN($W$1))) | Y5: =IF(X5<>"",VLOOKUP(X5,$A$1:$B$130,2,FALSE),0) -> 0 | AC5: =TRIM(MID(SUBSTITUTE($AB$1,"+",REPT(" ",LEN($AB$1))),(ROW()-ROW($AC$1)+1)*LEN($AB$1),LEN($AB$1))) | AD5: =IF(AC5<>"",VLOOKUP(AC5,$A$1:$B$130,2,FALSE),0) -> 0 | AH5: =TRIM(MID(SUBSTITUTE($AG$1,"+",REPT(" ",LEN($AG$1))),(ROW()-ROW($AH$1)+1)*LEN($AG$1),LEN($AG$1))) | AI5: =IF(AH5<>"",VLOOKUP(AH5,$A$1:$B$130,2,FALSE),0) -> 0 | AW5: 종류 별 합계
A6: =표!U6 -> 천 | B6: =표!V6 -> 80 | D6: =TRIM(MID(SUBSTITUTE($C$1,"+",REPT(" ",LEN($C$1))),(ROW()-ROW($D$1)+1)*LEN($C$1),LEN($C$1))) | E6: =IF(D6<>"",VLOOKUP(D6,$A$1:$B$130,2,FALSE),0) -> 0 | I6: =TRIM(MID(SUBSTITUTE($H$1,"+",REPT(" ",LEN($H$1))),(ROW()-ROW($I$1)+1)*LEN($H$1),LEN($H$1))) | J6: =IF(I6<>"",VLOOKUP(I6,$A$1:$B$130,2,FALSE),0) -> 0 | N6: =TRIM(MID(SUBSTITUTE($M$1,"+",REPT(" ",LEN($M$1))),(ROW()-ROW($N$1)+1)*LEN($M$1),LEN($M$1))) | O6: =IF(N6<>"",VLOOKUP(N6,$A$1:$B$130,2,FALSE),0) -> 0 | S6: =TRIM(MID(SUBSTITUTE($R$1,"+",REPT(" ",LEN($R$1))),(ROW()-ROW($S$1)+1)*LEN($R$1),LEN($R$1))) | T6: =IF(S6<>"",VLOOKUP(S6,$A$1:$B$130,2,FALSE),0) -> 0 | X6: =TRIM(MID(SUBSTITUTE($W$1,"+",REPT(" ",LEN($W$1))),(ROW()-ROW($X$1)+1)*LEN($W$1),LEN($W$1))) | Y6: =IF(X6<>"",VLOOKUP(X6,$A$1:$B$130,2,FALSE),0) -> 0 | AC6: =TRIM(MID(SUBSTITUTE($AB$1,"+",REPT(" ",LEN($AB$1))),(ROW()-ROW($AC$1)+1)*LEN($AB$1),LEN($AB$1))) | AD6: =IF(AC6<>"",VLOOKUP(AC6,$A$1:$B$130,2,FALSE),0) -> 0 | AH6: =TRIM(MID(SUBSTITUTE($AG$1,"+",REPT(" ",LEN($AG$1))),(ROW()-ROW($AH$1)+1)*LEN($AG$1),LEN($AG$1))) | AI6: =IF(AH6<>"",VLOOKUP(AH6,$A$1:$B$130,2,FALSE),0) -> 0 | AW6: 1. 장비 | AX6: =COUNTIF(표!$B$5:$B$300,"1.*") -> 4
A7: =표!U7 -> 전기부품 | B7: =표!V7 -> 96 | D7: =TRIM(MID(SUBSTITUTE($C$1,"+",REPT(" ",LEN($C$1))),(ROW()-ROW($D$1)+1)*LEN($C$1),LEN($C$1))) | E7: =IF(D7<>"",VLOOKUP(D7,$A$1:$B$130,2,FALSE),0) -> 0 | I7: =TRIM(MID(SUBSTITUTE($H$1,"+",REPT(" ",LEN($H$1))),(ROW()-ROW($I$1)+1)*LEN($H$1),LEN($H$1))) | J7: =IF(I7<>"",VLOOKUP(I7,$A$1:$B$130,2,FALSE),0) -> 0 | N7: =TRIM(MID(SUBSTITUTE($M$1,"+",REPT(" ",LEN($M$1))),(ROW()-ROW($N$1)+1)*LEN($M$1),LEN($M$1))) | O7: =IF(N7<>"",VLOOKUP(N7,$A$1:$B$130,2,FALSE),0) -> 0 | S7: =TRIM(MID(SUBSTITUTE($R$1,"+",REPT(" ",LEN($R$1))),(ROW()-ROW($S$1)+1)*LEN($R$1),LEN($R$1))) | T7: =IF(S7<>"",VLOOKUP(S7,$A$1:$B$130,2,FALSE),0) -> 0 | X7: =TRIM(MID(SUBSTITUTE($W$1,"+",REPT(" ",LEN($W$1))),(ROW()-ROW($X$1)+1)*LEN($W$1),LEN($W$1))) | Y7: =IF(X7<>"",VLOOKUP(X7,$A$1:$B$130,2,FALSE),0) -> 0 | AC7: =TRIM(MID(SUBSTITUTE($AB$1,"+",REPT(" ",LEN($AB$1))),(ROW()-ROW($AC$1)+1)*LEN($AB$1),LEN($AB$1))) | AD7: =IF(AC7<>"",VLOOKUP(AC7,$A$1:$B$130,2,FALSE),0) -> 0 | AH7: =TRIM(MID(SUBSTITUTE($AG$1,"+",REPT(" ",LEN($AG$1))),(ROW()-ROW($AH$1)+1)*LEN($AG$1),LEN($AG$1))) | AI7: =IF(AH7<>"",VLOOKUP(AH7,$A$1:$B$130,2,FALSE),0) -> 0 | AW7: 2. 도구 | AX7: =COUNTIF(표!$B$5:$B$300,"2.*") -> 8
A8: =표!U8 -> 산삼 | B8: =표!V8 -> 100 | D8: =TRIM(MID(SUBSTITUTE($C$1,"+",REPT(" ",LEN($C$1))),(ROW()-ROW($D$1)+1)*LEN($C$1),LEN($C$1))) | E8: =IF(D8<>"",VLOOKUP(D8,$A$1:$B$130,2,FALSE),0) -> 0 | I8: =TRIM(MID(SUBSTITUTE($H$1,"+",REPT(" ",LEN($H$1))),(ROW()-ROW($I$1)+1)*LEN($H$1),LEN($H$1))) | J8: =IF(I8<>"",VLOOKUP(I8,$A$1:$B$130,2,FALSE),0) -> 0 | N8: =TRIM(MID(SUBSTITUTE($M$1,"+",REPT(" ",LEN($M$1))),(ROW()-ROW($N$1)+1)*LEN($M$1),LEN($M$1))) | O8: =IF(N8<>"",VLOOKUP(N8,$A$1:$B$130,2,FALSE),0) -> 0 | S8: =TRIM(MID(SUBSTITUTE($R$1,"+",REPT(" ",LEN($R$1))),(ROW()-ROW($S$1)+1)*LEN($R$1),LEN($R$1))) | T8: =IF(S8<>"",VLOOKUP(S8,$A$1:$B$130,2,FALSE),0) -> 0 | X8: =TRIM(MID(SUBSTITUTE($W$1,"+",REPT(" ",LEN($W$1))),(ROW()-ROW($X$1)+1)*LEN($W$1),LEN($W$1))) | Y8: =IF(X8<>"",VLOOKUP(X8,$A$1:$B$130,2,FALSE),0) -> 0 | AC8: =TRIM(MID(SUBSTITUTE($AB$1,"+",REPT(" ",LEN($AB$1))),(ROW()-ROW($AC$1)+1)*LEN($AB$1),LEN($AB$1))) | AD8: =IF(AC8<>"",VLOOKUP(AC8,$A$1:$B$130,2,FALSE),0) -> 0 | AH8: =TRIM(MID(SUBSTITUTE($AG$1,"+",REPT(" ",LEN($AG$1))),(ROW()-ROW($AH$1)+1)*LEN($AG$1),LEN($AG$1))) | AI8: =IF(AH8<>"",VLOOKUP(AH8,$A$1:$B$130,2,FALSE),0) -> 0 | AW8: 3. 공격 | AX8: =COUNTIF(표!$B$5:$B$300,"3.*") -> 5
A9: =표!S9 -> 큰 물고기 | B9: =표!T9 -> 32 | D9: =TRIM(MID(SUBSTITUTE($C$1,"+",REPT(" ",LEN($C$1))),(ROW()-ROW($D$1)+1)*LEN($C$1),LEN($C$1))) | E9: =IF(D9<>"",VLOOKUP(D9,$A$1:$B$130,2,FALSE),0) -> 0 | I9: =TRIM(MID(SUBSTITUTE($H$1,"+",REPT(" ",LEN($H$1))),(ROW()-ROW($I$1)+1)*LEN($H$1),LEN($H$1))) | J9: =IF(I9<>"",VLOOKUP(I9,$A$1:$B$130,2,FALSE),0) -> 0 | N9: =TRIM(MID(SUBSTITUTE($M$1,"+",REPT(" ",LEN($M$1))),(ROW()-ROW($N$1)+1)*LEN($M$1),LEN($M$1))) | O9: =IF(N9<>"",VLOOKUP(N9,$A$1:$B$130,2,FALSE),0) -> 0 | S9: =TRIM(MID(SUBSTITUTE($R$1,"+",REPT(" ",LEN($R$1))),(ROW()-ROW($S$1)+1)*LEN($R$1),LEN($R$1))) | T9: =IF(S9<>"",VLOOKUP(S9,$A$1:$B$130,2,FALSE),0) -> 0 | X9: =TRIM(MID(SUBSTITUTE($W$1,"+",REPT(" ",LEN($W$1))),(ROW()-ROW($X$1)+1)*LEN($W$1),LEN($W$1))) | Y9: =IF(X9<>"",VLOOKUP(X9,$A$1:$B$130,2,FALSE),0) -> 0 | AC9: =TRIM(MID(SUBSTITUTE($AB$1,"+",REPT(" ",LEN($AB$1))),(ROW()-ROW($AC$1)+1)*LEN($AB$1),LEN($AB$1))) | AD9: =IF(AC9<>"",VLOOKUP(AC9,$A$1:$B$130,2,FALSE),0) -> 0 | AH9: =TRIM(MID(SUBSTITUTE($AG$1,"+",REPT(" ",LEN($AG$1))),(ROW()-ROW($AH$1)+1)*LEN($AG$1),LEN($AG$1))) | AI9: =IF(AH9<>"",VLOOKUP(AH9,$A$1:$B$130,2,FALSE),0) -> 0 | AW9: 4. 섭취 | AX9: =COUNTIF(표!$B$5:$B$300,"4.*") -> 4
A10: =표!S10 -> 철 | B10: =표!T10 -> 32 | D10: =TRIM(MID(SUBSTITUTE($C$1,"+",REPT(" ",LEN($C$1))),(ROW()-ROW($D$1)+1)*LEN($C$1),LEN($C$1))) | E10: =IF(D10<>"",VLOOKUP(D10,$A$1:$B$130,2,FALSE),0) -> 0 | I10: =TRIM(MID(SUBSTITUTE($H$1,"+",REPT(" ",LEN($H$1))),(ROW()-ROW($I$1)+1)*LEN($H$1),LEN($H$1))) | J10: =IF(I10<>"",VLOOKUP(I10,$A$1:$B$130,2,FALSE),0) -> 0 | N10: =TRIM(MID(SUBSTITUTE($M$1,"+",REPT(" ",LEN($M$1))),(ROW()-ROW($N$1)+1)*LEN($M$1),LEN($M$1))) | O10: =IF(N10<>"",VLOOKUP(N10,$A$1:$B$130,2,FALSE),0) -> 0 | S10: =TRIM(MID(SUBSTITUTE($R$1,"+",REPT(" ",LEN($R$1))),(ROW()-ROW($S$1)+1)*LEN($R$1),LEN($R$1))) | T10: =IF(S10<>"",VLOOKUP(S10,$A$1:$B$130,2,FALSE),0) -> 0 | X10: =TRIM(MID(SUBSTITUTE($W$1,"+",REPT(" ",LEN($W$1))),(ROW()-ROW($X$1)+1)*LEN($W$1),LEN($W$1))) | Y10: =IF(X10<>"",VLOOKUP(X10,$A$1:$B$130,2,FALSE),0) -> 0 | AC10: =TRIM(MID(SUBSTITUTE($AB$1,"+",REPT(" ",LEN($AB$1))),(ROW()-ROW($AC$1)+1)*LEN($AB$1),LEN($AB$1))) | AD10: =IF(AC10<>"",VLOOKUP(AC10,$A$1:$B$130,2,FALSE),0) -> 0 | AH10: =TRIM(MID(SUBSTITUTE($AG$1,"+",REPT(" ",LEN($AG$1))),(ROW()-ROW($AH$1)+1)*LEN($AG$1),LEN($AG$1))) | AI10: =IF(AH10<>"",VLOOKUP(AH10,$A$1:$B$130,2,FALSE),0) -> 0 | AW10: 5. 설치 | AX10: =COUNTIF(표!$B$5:$B$300,"5.*") -> 5
A11: =표!S11 -> 황동 | B11: =표!T11 -> 64 | C11: 1 | H11: 2 | M11: 3 | R11: 4 | W11: 5 | AB11: 6 | AG11: 7
A12: =표!S12 -> 화약 | B12: =표!T12 -> 80
A13: =표!U9 -> 다이아몬드 | B13: =표!V9 -> 100 | C13: =표!Y12 -> +나무+황동 | D13: =TRIM(MID(SUBSTITUTE($C$13,"+",REPT(" ",LEN($C$13))),(ROW()-ROW($D$13)+1)*LEN($C$13),LEN($C$13))) -> 나무 | E13: =IF(D13<>"",VLOOKUP(D13,$A$1:$B$130,2,FALSE),0) -> 16 | F13: =SUM(E13:E22) -> 80 | H13: =표!Y13 -> +마법석+나무+황동 | I13: =TRIM(MID(SUBSTITUTE($H$13,"+",REPT(" ",LEN($H$13))),(ROW()-ROW($I$13)+1)*LEN($H$13),LEN($H$13))) -> 마법석 | J13: =IF(I13<>"",VLOOKUP(I13,$A$1:$B$130,2,FALSE),0) -> 128 | K13: =SUM(J13:J22) -> 208 | M13: =표!Y14 -> +나무+화약 | N13: =TRIM(MID(SUBSTITUTE($M$13,"+",REPT(" ",LEN($M$13))),(ROW()-ROW($N$13)+1)*LEN($M$13),LEN($M$13))) -> 나무 | O13: =IF(N13<>"",VLOOKUP(N13,$A$1:$B$130,2,FALSE),0) -> 16 | P13: =SUM(O13:O22) -> 96 | R13: =표!Y15 -> +마법석+황동+화약 | S13: =TRIM(MID(SUBSTITUTE($R$13,"+",REPT(" ",LEN($R$13))),(ROW()-ROW($S$13)+1)*LEN($R$13),LEN($R$13))) -> 마법석 | T13: =IF(S13<>"",VLOOKUP(S13,$A$1:$B$130,2,FALSE),0) -> 128 | U13: =SUM(T13:T22) -> 272 | W13: =표!Y16 -> +나무+나무 | X13: =TRIM(MID(SUBSTITUTE($W$13,"+",REPT(" ",LEN($W$13))),(ROW()-ROW($X$13)+1)*LEN($W$13),LEN($W$13))) -> 나무 | Y13: =IF(X13<>"",VLOOKUP(X13,$A$1:$B$130,2,FALSE),0) -> 16 | Z13: =SUM(Y13:Y22) -> 32 | AB13: =표!Y17 -> +나무+나무+철+철 | AC13: =TRIM(MID(SUBSTITUTE($AB$13,"+",REPT(" ",LEN($AB$13))),(ROW()-ROW($AC$13)+1)*LEN($AB$13),LEN($AB$13))) -> 나무 | AD13: =IF(AC13<>"",VLOOKUP(AC13,$A$1:$B$130,2,FALSE),0) -> 16 | AE13: =SUM(AD13:AD22) -> 96 | AG13: =표!Y18 -> +나무+철+철+다이아몬드+천 | AH13: =TRIM(MID(SUBSTITUTE($AG$13,"+",REPT(" ",LEN($AG$13))),(ROW()-ROW($AH$13)+1)*LEN($AG$13),LEN($AG$13))) -> 나무 | AI13: =IF(AH13<>"",VLOOKUP(AH13,$A$1:$B$130,2,FALSE),0) -> 16 | AJ13: =SUM(AI13:AI22) -> 260
A14: =표!U10 -> 상어 | B14: =표!V10 -> 100 | D14: =TRIM(MID(SUBSTITUTE($C$13,"+",REPT(" ",LEN($C$13))),(ROW()-ROW($D$13)+1)*LEN($C$13),LEN($C$13))) -> 황동 | E14: =IF(D14<>"",VLOOKUP(D14,$A$1:$B$130,2,FALSE),0) -> 64 | I14: =TRIM(MID(SUBSTITUTE($H$13,"+",REPT(" ",LEN($H$13))),(ROW()-ROW($I$13)+1)*LEN($H$13),LEN($H$13))) -> 나무 | J14: =IF(I14<>"",VLOOKUP(I14,$A$1:$B$130,2,FALSE),0) -> 16 | N14: =TRIM(MID(SUBSTITUTE($M$13,"+",REPT(" ",LEN($M$13))),(ROW()-ROW($N$13)+1)*LEN($M$13),LEN($M$13))) -> 화약 | O14: =IF(N14<>"",VLOOKUP(N14,$A$1:$B$130,2,FALSE),0) -> 80 | S14: =TRIM(MID(SUBSTITUTE($R$13,"+",REPT(" ",LEN($R$13))),(ROW()-ROW($S$13)+1)*LEN($R$13),LEN($R$13))) -> 황동 | T14: =IF(S14<>"",VLOOKUP(S14,$A$1:$B$130,2,FALSE),0) -> 64 | X14: =TRIM(MID(SUBSTITUTE($W$13,"+",REPT(" ",LEN($W$13))),(ROW()-ROW($X$13)+1)*LEN($W$13),LEN($W$13))) -> 나무 | Y14: =IF(X14<>"",VLOOKUP(X14,$A$1:$B$130,2,FALSE),0) -> 16 | AC14: =TRIM(MID(SUBSTITUTE($AB$13,"+",REPT(" ",LEN($AB$13))),(ROW()-ROW($AC$13)+1)*LEN($AB$13),LEN($AB$13))) -> 나무 | AD14: =IF(AC14<>"",VLOOKUP(AC14,$A$1:$B$130,2,FALSE),0) -> 16 | AH14: =TRIM(MID(SUBSTITUTE($AG$13,"+",REPT(" ",LEN($AG$13))),(ROW()-ROW($AH$13)+1)*LEN($AG$13),LEN($AG$13))) -> 철 | AI14: =IF(AH14<>"",VLOOKUP(AH14,$A$1:$B$130,2,FALSE),0) -> 32
A15: =표!U11 -> 마법석 | B15: =표!V11 -> 128 | D15: =TRIM(MID(SUBSTITUTE($C$13,"+",REPT(" ",LEN($C$13))),(ROW()-ROW($D$13)+1)*LEN($C$13),LEN($C$13))) | E15: =IF(D15<>"",VLOOKUP(D15,$A$1:$B$130,2,FALSE),0) -> 0 | I15: =TRIM(MID(SUBSTITUTE($H$13,"+",REPT(" ",LEN($H$13))),(ROW()-ROW($I$13)+1)*LEN($H$13),LEN($H$13))) -> 황동 | J15: =IF(I15<>"",VLOOKUP(I15,$A$1:$B$130,2,FALSE),0) -> 64 | N15: =TRIM(MID(SUBSTITUTE($M$13,"+",REPT(" ",LEN($M$13))),(ROW()-ROW($N$13)+1)*LEN($M$13),LEN($M$13))) | O15: =IF(N15<>"",VLOOKUP(N15,$A$1:$B$130,2,FALSE),0) -> 0 | S15: =TRIM(MID(SUBSTITUTE($R$13,"+",REPT(" ",LEN($R$13))),(ROW()-ROW($S$13)+1)*LEN($R$13),LEN($R$13))) -> 화약 | T15: =IF(S15<>"",VLOOKUP(S15,$A$1:$B$130,2,FALSE),0) -> 80 | X15: =TRIM(MID(SUBSTITUTE($W$13,"+",REPT(" ",LEN($W$13))),(ROW()-ROW($X$13)+1)*LEN($W$13),LEN($W$13))) | Y15: =IF(X15<>"",VLOOKUP(X15,$A$1:$B$130,2,FALSE),0) -> 0 | AC15: =TRIM(MID(SUBSTITUTE($AB$13,"+",REPT(" ",LEN($AB$13))),(ROW()-ROW($AC$13)+1)*LEN($AB$13),LEN($AB$13))) -> 철 | AD15: =IF(AC15<>"",VLOOKUP(AC15,$A$1:$B$130,2,FALSE),0) -> 32 | AH15: =TRIM(MID(SUBSTITUTE($AG$13,"+",REPT(" ",LEN($AG$13))),(ROW()-ROW($AH$13)+1)*LEN($AG$13),LEN($AG$13))) -> 철 | AI15: =IF(AH15<>"",VLOOKUP(AH15,$A$1:$B$130,2,FALSE),0) -> 32
A16: =표!U12 -> 총기부품 | B16: =표!V12 -> 144 | D16: =TRIM(MID(SUBSTITUTE($C$13,"+",REPT(" ",LEN($C$13))),(ROW()-ROW($D$13)+1)*LEN($C$13),LEN($C$13))) | E16: =IF(D16<>"",VLOOKUP(D16,$A$1:$B$130,2,FALSE),0) -> 0 | I16: =TRIM(MID(SUBSTITUTE($H$13,"+",REPT(" ",LEN($H$13))),(ROW()-ROW($I$13)+1)*LEN($H$13),LEN($H$13))) | J16: =IF(I16<>"",VLOOKUP(I16,$A$1:$B$130,2,FALSE),0) -> 0 | N16: =TRIM(MID(SUBSTITUTE($M$13,"+",REPT(" ",LEN($M$13))),(ROW()-ROW($N$13)+1)*LEN($M$13),LEN($M$13))) | O16: =IF(N16<>"",VLOOKUP(N16,$A$1:$B$130,2,FALSE),0) -> 0 | S16: =TRIM(MID(SUBSTITUTE($R$13,"+",REPT(" ",LEN($R$13))),(ROW()-ROW($S$13)+1)*LEN($R$13),LEN($R$13))) | T16: =IF(S16<>"",VLOOKUP(S16,$A$1:$B$130,2,FALSE),0) -> 0 | X16: =TRIM(MID(SUBSTITUTE($W$13,"+",REPT(" ",LEN($W$13))),(ROW()-ROW($X$13)+1)*LEN($W$13),LEN($W$13))) | Y16: =IF(X16<>"",VLOOKUP(X16,$A$1:$B$130,2,FALSE),0) -> 0 | AC16: =TRIM(MID(SUBSTITUTE($AB$13,"+",REPT(" ",LEN($AB$13))),(ROW()-ROW($AC$13)+1)*LEN($AB$13),LEN($AB$13))) -> 철 | AD16: =IF(AC16<>"",VLOOKUP(AC16,$A$1:$B$130,2,FALSE),0) -> 32 | AH16: =TRIM(MID(SUBSTITUTE($AG$13,"+",REPT(" ",LEN($AG$13))),(ROW()-ROW($AH$13)+1)*LEN($AG$13),LEN($AG$13))) -> 다이아몬드 | AI16: =IF(AH16<>"",VLOOKUP(AH16,$A$1:$B$130,2,FALSE),0) -> 100
D17: =TRIM(MID(SUBSTITUTE($C$13,"+",REPT(" ",LEN($C$13))),(ROW()-ROW($D$13)+1)*LEN($C$13),LEN($C$13))) | E17: =IF(D17<>"",VLOOKUP(D17,$A$1:$B$130,2,FALSE),0) -> 0 | I17: =TRIM(MID(SUBSTITUTE($H$13,"+",REPT(" ",LEN($H$13))),(ROW()-ROW($I$13)+1)*LEN($H$13),LEN($H$13))) | J17: =IF(I17<>"",VLOOKUP(I17,$A$1:$B$130,2,FALSE),0) -> 0 | N17: =TRIM(MID(SUBSTITUTE($M$13,"+",REPT(" ",LEN($M$13))),(ROW()-ROW($N$13)+1)*LEN($M$13),LEN($M$13))) | O17: =IF(N17<>"",VLOOKUP(N17,$A$1:$B$130,2,FALSE),0) -> 0 | S17: =TRIM(MID(SUBSTITUTE($R$13,"+",REPT(" ",LEN($R$13))),(ROW()-ROW($S$13)+1)*LEN($R$13),LEN($R$13))) | T17: =IF(S17<>"",VLOOKUP(S17,$A$1:$B$130,2,FALSE),0) -> 0 | X17: =TRIM(MID(SUBSTITUTE($W$13,"+",REPT(" ",LEN($W$13))),(ROW()-ROW($X$13)+1)*LEN($W$13),LEN($W$13))) | Y17: =IF(X17<>"",VLOOKUP(X17,$A$1:$B$130,2,FALSE),0) -> 0 | AC17: =TRIM(MID(SUBSTITUTE($AB$13,"+",REPT(" ",LEN($AB$13))),(ROW()-ROW($AC$13)+1)*LEN($AB$13),LEN($AB$13))) | AD17: =IF(AC17<>"",VLOOKUP(AC17,$A$1:$B$130,2,FALSE),0) -> 0 | AH17: =TRIM(MID(SUBSTITUTE($AG$13,"+",REPT(" ",LEN($AG$13))),(ROW()-ROW($AH$13)+1)*LEN($AG$13),LEN($AG$13))) -> 천 | AI17: =IF(AH17<>"",VLOOKUP(AH17,$A$1:$B$130,2,FALSE),0) -> 80
D18: =TRIM(MID(SUBSTITUTE($C$13,"+",REPT(" ",LEN($C$13))),(ROW()-ROW($D$13)+1)*LEN($C$13),LEN($C$13))) | E18: =IF(D18<>"",VLOOKUP(D18,$A$1:$B$130,2,FALSE),0) -> 0 | I18: =TRIM(MID(SUBSTITUTE($H$13,"+",REPT(" ",LEN($H$13))),(ROW()-ROW($I$13)+1)*LEN($H$13),LEN($H$13))) | J18: =IF(I18<>"",VLOOKUP(I18,$A$1:$B$130,2,FALSE),0) -> 0 | N18: =TRIM(MID(SUBSTITUTE($M$13,"+",REPT(" ",LEN($M$13))),(ROW()-ROW($N$13)+1)*LEN($M$13),LEN($M$13))) | O18: =IF(N18<>"",VLOOKUP(N18,$A$1:$B$130,2,FALSE),0) -> 0 | S18: =TRIM(MID(SUBSTITUTE($R$13,"+",REPT(" ",LEN($R$13))),(ROW()-ROW($S$13)+1)*LEN($R$13),LEN($R$13))) | T18: =IF(S18<>"",VLOOKUP(S18,$A$1:$B$130,2,FALSE),0) -> 0 | X18: =TRIM(MID(SUBSTITUTE($W$13,"+",REPT(" ",LEN($W$13))),(ROW()-ROW($X$13)+1)*LEN($W$13),LEN($W$13))) | Y18: =IF(X18<>"",VLOOKUP(X18,$A$1:$B$130,2,FALSE),0) -> 0 | AC18: =TRIM(MID(SUBSTITUTE($AB$13,"+",REPT(" ",LEN($AB$13))),(ROW()-ROW($AC$13)+1)*LEN($AB$13),LEN($AB$13))) | AD18: =IF(AC18<>"",VLOOKUP(AC18,$A$1:$B$130,2,FALSE),0) -> 0 | AH18: =TRIM(MID(SUBSTITUTE($AG$13,"+",REPT(" ",LEN($AG$13))),(ROW()-ROW($AH$13)+1)*LEN($AG$13),LEN($AG$13))) | AI18: =IF(AH18<>"",VLOOKUP(AH18,$A$1:$B$130,2,FALSE),0) -> 0
D19: =TRIM(MID(SUBSTITUTE($C$13,"+",REPT(" ",LEN($C$13))),(ROW()-ROW($D$13)+1)*LEN($C$13),LEN($C$13))) | E19: =IF(D19<>"",VLOOKUP(D19,$A$1:$B$130,2,FALSE),0) -> 0 | I19: =TRIM(MID(SUBSTITUTE($H$13,"+",REPT(" ",LEN($H$13))),(ROW()-ROW($I$13)+1)*LEN($H$13),LEN($H$13))) | J19: =IF(I19<>"",VLOOKUP(I19,$A$1:$B$130,2,FALSE),0) -> 0 | N19: =TRIM(MID(SUBSTITUTE($M$13,"+",REPT(" ",LEN($M$13))),(ROW()-ROW($N$13)+1)*LEN($M$13),LEN($M$13))) | O19: =IF(N19<>"",VLOOKUP(N19,$A$1:$B$130,2,FALSE),0) -> 0 | S19: =TRIM(MID(SUBSTITUTE($R$13,"+",REPT(" ",LEN($R$13))),(ROW()-ROW($S$13)+1)*LEN($R$13),LEN($R$13))) | T19: =IF(S19<>"",VLOOKUP(S19,$A$1:$B$130,2,FALSE),0) -> 0 | X19: =TRIM(MID(SUBSTITUTE($W$13,"+",REPT(" ",LEN($W$13))),(ROW()-ROW($X$13)+1)*LEN($W$13),LEN($W$13))) | Y19: =IF(X19<>"",VLOOKUP(X19,$A$1:$B$130,2,FALSE),0) -> 0 | AC19: =TRIM(MID(SUBSTITUTE($AB$13,"+",REPT(" ",LEN($AB$13))),(ROW()-ROW($AC$13)+1)*LEN($AB$13),LEN($AB$13))) | AD19: =IF(AC19<>"",VLOOKUP(AC19,$A$1:$B$130,2,FALSE),0) -> 0 | AH19: =TRIM(MID(SUBSTITUTE($AG$13,"+",REPT(" ",LEN($AG$13))),(ROW()-ROW($AH$13)+1)*LEN($AG$13),LEN($AG$13))) | AI19: =IF(AH19<>"",VLOOKUP(AH19,$A$1:$B$130,2,FALSE),0) -> 0
D20: =TRIM(MID(SUBSTITUTE($C$13,"+",REPT(" ",LEN($C$13))),(ROW()-ROW($D$13)+1)*LEN($C$13),LEN($C$13))) | E20: =IF(D20<>"",VLOOKUP(D20,$A$1:$B$130,2,FALSE),0) -> 0 | I20: =TRIM(MID(SUBSTITUTE($H$13,"+",REPT(" ",LEN($H$13))),(ROW()-ROW($I$13)+1)*LEN($H$13),LEN($H$13))) | J20: =IF(I20<>"",VLOOKUP(I20,$A$1:$B$130,2,FALSE),0) -> 0 | N20: =TRIM(MID(SUBSTITUTE($M$13,"+",REPT(" ",LEN($M$13))),(ROW()-ROW($N$13)+1)*LEN($M$13),LEN($M$13))) | O20: =IF(N20<>"",VLOOKUP(N20,$A$1:$B$130,2,FALSE),0) -> 0 | S20: =TRIM(MID(SUBSTITUTE($R$13,"+",REPT(" ",LEN($R$13))),(ROW()-ROW($S$13)+1)*LEN($R$13),LEN($R$13))) | T20: =IF(S20<>"",VLOOKUP(S20,$A$1:$B$130,2,FALSE),0) -> 0 | X20: =TRIM(MID(SUBSTITUTE($W$13,"+",REPT(" ",LEN($W$13))),(ROW()-ROW($X$13)+1)*LEN($W$13),LEN($W$13))) | Y20: =IF(X20<>"",VLOOKUP(X20,$A$1:$B$130,2,FALSE),0) -> 0 | AC20: =TRIM(MID(SUBSTITUTE($AB$13,"+",REPT(" ",LEN($AB$13))),(ROW()-ROW($AC$13)+1)*LEN($AB$13),LEN($AB$13))) | AD20: =IF(AC20<>"",VLOOKUP(AC20,$A$1:$B$130,2,FALSE),0) -> 0 | AH20: =TRIM(MID(SUBSTITUTE($AG$13,"+",REPT(" ",LEN($AG$13))),(ROW()-ROW($AH$13)+1)*LEN($AG$13),LEN($AG$13))) | AI20: =IF(AH20<>"",VLOOKUP(AH20,$A$1:$B$130,2,FALSE),0) -> 0
D21: =TRIM(MID(SUBSTITUTE($C$13,"+",REPT(" ",LEN($C$13))),(ROW()-ROW($D$13)+1)*LEN($C$13),LEN($C$13))) | E21: =IF(D21<>"",VLOOKUP(D21,$A$1:$B$130,2,FALSE),0) -> 0 | I21: =TRIM(MID(SUBSTITUTE($H$13,"+",REPT(" ",LEN($H$13))),(ROW()-ROW($I$13)+1)*LEN($H$13),LEN($H$13))) | J21: =IF(I21<>"",VLOOKUP(I21,$A$1:$B$130,2,FALSE),0) -> 0 | N21: =TRIM(MID(SUBSTITUTE($M$13,"+",REPT(" ",LEN($M$13))),(ROW()-ROW($N$13)+1)*LEN($M$13),LEN($M$13))) | O21: =IF(N21<>"",VLOOKUP(N21,$A$1:$B$130,2,FALSE),0) -> 0 | S21: =TRIM(MID(SUBSTITUTE($R$13,"+",REPT(" ",LEN($R$13))),(ROW()-ROW($S$13)+1)*LEN($R$13),LEN($R$13))) | T21: =IF(S21<>"",VLOOKUP(S21,$A$1:$B$130,2,FALSE),0) -> 0 | X21: =TRIM(MID(SUBSTITUTE($W$13,"+",REPT(" ",LEN($W$13))),(ROW()-ROW($X$13)+1)*LEN($W$13),LEN($W$13))) | Y21: =IF(X21<>"",VLOOKUP(X21,$A$1:$B$130,2,FALSE),0) -> 0 | AC21: =TRIM(MID(SUBSTITUTE($AB$13,"+",REPT(" ",LEN($AB$13))),(ROW()-ROW($AC$13)+1)*LEN($AB$13),LEN($AB$13))) | AD21: =IF(AC21<>"",VLOOKUP(AC21,$A$1:$B$130,2,FALSE),0) -> 0 | AH21: =TRIM(MID(SUBSTITUTE($AG$13,"+",REPT(" ",LEN($AG$13))),(ROW()-ROW($AH$13)+1)*LEN($AG$13),LEN($AG$13))) | AI21: =IF(AH21<>"",VLOOKUP(AH21,$A$1:$B$130,2,FALSE),0) -> 0
D22: =TRIM(MID(SUBSTITUTE($C$13,"+",REPT(" ",LEN($C$13))),(ROW()-ROW($D$13)+1)*LEN($C$13),LEN($C$13))) | E22: =IF(D22<>"",VLOOKUP(D22,$A$1:$B$130,2,FALSE),0) -> 0 | I22: =TRIM(MID(SUBSTITUTE($H$13,"+",REPT(" ",LEN($H$13))),(ROW()-ROW($I$13)+1)*LEN($H$13),LEN($H$13))) | J22: =IF(I22<>"",VLOOKUP(I22,$A$1:$B$130,2,FALSE),0) -> 0 | N22: =TRIM(MID(SUBSTITUTE($M$13,"+",REPT(" ",LEN($M$13))),(ROW()-ROW($N$13)+1)*LEN($M$13),LEN($M$13))) | O22: =IF(N22<>"",VLOOKUP(N22,$A$1:$B$130,2,FALSE),0) -> 0 | S22: =TRIM(MID(SUBSTITUTE($R$13,"+",REPT(" ",LEN($R$13))),(ROW()-ROW($S$13)+1)*LEN($R$13),LEN($R$13))) | T22: =IF(S22<>"",VLOOKUP(S22,$A$1:$B$130,2,FALSE),0) -> 0 | X22: =TRIM(MID(SUBSTITUTE($W$13,"+",REPT(" ",LEN($W$13))),(ROW()-ROW($X$13)+1)*LEN($W$13),LEN($W$13))) | Y22: =IF(X22<>"",VLOOKUP(X22,$A$1:$B$130,2,FALSE),0) -> 0 | AC22: =TRIM(MID(SUBSTITUTE($AB$13,"+",REPT(" ",LEN($AB$13))),(ROW()-ROW($AC$13)+1)*LEN($AB$13),LEN($AB$13))) | AD22: =IF(AC22<>"",VLOOKUP(AC22,$A$1:$B$130,2,FALSE),0) -> 0 | AH22: =TRIM(MID(SUBSTITUTE($AG$13,"+",REPT(" ",LEN($AG$13))),(ROW()-ROW($AH$13)+1)*LEN($AG$13),LEN($AG$13))) | AI22: =IF(AH22<>"",VLOOKUP(AH22,$A$1:$B$130,2,FALSE),0) -> 0
C23: 8 | H23: 9 | M23: 10 | R23: 11 | W23: 12 | AB23: 13 | AG23: 14
M24: +
C25: =표!Y19 -> +총기부품+나무+철 | D25: =TRIM(MID(SUBSTITUTE($C$25,"+",REPT(" ",LEN($C$25))),(ROW()-ROW($D$25)+1)*LEN($C$25),LEN($C$25))) -> 총기부품 | E25: =IF(D25<>"",VLOOKUP(D25,$A$1:$B$130,2,FALSE),0) -> 144 | F25: =SUM(E25:E34) -> 192 | H25: =표!Y20 -> +철+황동+화약 | I25: =TRIM(MID(SUBSTITUTE($H$25,"+",REPT(" ",LEN($H$25))),(ROW()-ROW($I$25)+1)*LEN($H$25),LEN($H$25))) -> 철 | J25: =IF(I25<>"",VLOOKUP(I25,$A$1:$B$130,2,FALSE),0) -> 32 | K25: =SUM(J25:J34) -> 176 | M25: =표!Y21 -> +나무+나무+철 | N25: =TRIM(MID(SUBSTITUTE($M$25,"+",REPT(" ",LEN($M$25))),(ROW()-ROW($N$25)+1)*LEN($M$25),LEN($M$25))) -> 나무 | O25: =IF(N25<>"",VLOOKUP(N25,$A$1:$B$130,2,FALSE),0) -> 16 | P25: =SUM(O25:O34) -> 64 | R25: =표!Y22 -> +나무+나무+나무+철+황동 | S25: =TRIM(MID(SUBSTITUTE($R$25,"+",REPT(" ",LEN($R$25))),(ROW()-ROW($S$25)+1)*LEN($R$25),LEN($R$25))) -> 나무 | T25: =IF(S25<>"",VLOOKUP(S25,$A$1:$B$130,2,FALSE),0) -> 16 | U25: =SUM(T25:T34) -> 144 | W25: =표!Y23 -> +나무+나무+철+천 | X25: =TRIM(MID(SUBSTITUTE($W$25,"+",REPT(" ",LEN($W$25))),(ROW()-ROW($X$25)+1)*LEN($W$25),LEN($W$25))) -> 나무 | Y25: =IF(X25<>"",VLOOKUP(X25,$A$1:$B$130,2,FALSE),0) -> 16 | Z25: =SUM(Y25:Y34) -> 144 | AB25: =표!Y24 -> +나무+나무+천 | AC25: =TRIM(MID(SUBSTITUTE($AB$25,"+",REPT(" ",LEN($AB$25))),(ROW()-ROW($AC$25)+1)*LEN($AB$25),LEN($AB$25))) -> 나무 | AD25: =IF(AC25<>"",VLOOKUP(AC25,$A$1:$B$130,2,FALSE),0) -> 16 | AE25: =SUM(AD25:AD34) -> 112 | AG25: =표!Y25 -> +단 열매+쓴 열매+철 | AH25: =TRIM(MID(SUBSTITUTE($AG$25,"+",REPT(" ",LEN($AG$25))),(ROW()-ROW($AH$25)+1)*LEN($AG$25),LEN($AG$25))) -> 단 열매 | AI25: =IF(AH25<>"",VLOOKUP(AH25,$A$1:$B$130,2,FALSE),0) -> 16 | AJ25: =SUM(AI25:AI34) -> 64
D26: =TRIM(MID(SUBSTITUTE($C$25,"+",REPT(" ",LEN($C$25))),(ROW()-ROW($D$25)+1)*LEN($C$25),LEN($C$25))) -> 나무 | E26: =IF(D26<>"",VLOOKUP(D26,$A$1:$B$130,2,FALSE),0) -> 16 | I26: =TRIM(MID(SUBSTITUTE($H$25,"+",REPT(" ",LEN($H$25))),(ROW()-ROW($I$25)+1)*LEN($H$25),LEN($H$25))) -> 황동 | J26: =IF(I26<>"",VLOOKUP(I26,$A$1:$B$130,2,FALSE),0) -> 64 | N26: =TRIM(MID(SUBSTITUTE($M$25,"+",REPT(" ",LEN($M$25))),(ROW()-ROW($N$25)+1)*LEN($M$25),LEN($M$25))) -> 나무 | O26: =IF(N26<>"",VLOOKUP(N26,$A$1:$B$130,2,FALSE),0) -> 16 | S26: =TRIM(MID(SUBSTITUTE($R$25,"+",REPT(" ",LEN($R$25))),(ROW()-ROW($S$25)+1)*LEN($R$25),LEN($R$25))) -> 나무 | T26: =IF(S26<>"",VLOOKUP(S26,$A$1:$B$130,2,FALSE),0) -> 16 | X26: =TRIM(MID(SUBSTITUTE($W$25,"+",REPT(" ",LEN($W$25))),(ROW()-ROW($X$25)+1)*LEN($W$25),LEN($W$25))) -> 나무 | Y26: =IF(X26<>"",VLOOKUP(X26,$A$1:$B$130,2,FALSE),0) -> 16 | AC26: =TRIM(MID(SUBSTITUTE($AB$25,"+",REPT(" ",LEN($AB$25))),(ROW()-ROW($AC$25)+1)*LEN($AB$25),LEN($AB$25))) -> 나무 | AD26: =IF(AC26<>"",VLOOKUP(AC26,$A$1:$B$130,2,FALSE),0) -> 16 | AH26: =TRIM(MID(SUBSTITUTE($AG$25,"+",REPT(" ",LEN($AG$25))),(ROW()-ROW($AH$25)+1)*LEN($AG$25),LEN($AG$25))) -> 쓴 열매 | AI26: =IF(AH26<>"",VLOOKUP(AH26,$A$1:$B$130,2,FALSE),0) -> 16
D27: =TRIM(MID(SUBSTITUTE($C$25,"+",REPT(" ",LEN($C$25))),(ROW()-ROW($D$25)+1)*LEN($C$25),LEN($C$25))) -> 철 | E27: =IF(D27<>"",VLOOKUP(D27,$A$1:$B$130,2,FALSE),0) -> 32 | I27: =TRIM(MID(SUBSTITUTE($H$25,"+",REPT(" ",LEN($H$25))),(ROW()-ROW($I$25)+1)*LEN($H$25),LEN($H$25))) -> 화약 | J27: =IF(I27<>"",VLOOKUP(I27,$A$1:$B$130,2,FALSE),0) -> 80 | N27: =TRIM(MID(SUBSTITUTE($M$25,"+",REPT(" ",LEN($M$25))),(ROW()-ROW($N$25)+1)*LEN($M$25),LEN($M$25))) -> 철 | O27: =IF(N27<>"",VLOOKUP(N27,$A$1:$B$130,2,FALSE),0) -> 32 | S27: =TRIM(MID(SUBSTITUTE($R$25,"+",REPT(" ",LEN($R$25))),(ROW()-ROW($S$25)+1)*LEN($R$25),LEN($R$25))) -> 나무 | T27: =IF(S27<>"",VLOOKUP(S27,$A$1:$B$130,2,FALSE),0) -> 16 | X27: =TRIM(MID(SUBSTITUTE($W$25,"+",REPT(" ",LEN($W$25))),(ROW()-ROW($X$25)+1)*LEN($W$25),LEN($W$25))) -> 철 | Y27: =IF(X27<>"",VLOOKUP(X27,$A$1:$B$130,2,FALSE),0) -> 32 | AC27: =TRIM(MID(SUBSTITUTE($AB$25,"+",REPT(" ",LEN($AB$25))),(ROW()-ROW($AC$25)+1)*LEN($AB$25),LEN($AB$25))) -> 천 | AD27: =IF(AC27<>"",VLOOKUP(AC27,$A$1:$B$130,2,FALSE),0) -> 80 | AH27: =TRIM(MID(SUBSTITUTE($AG$25,"+",REPT(" ",LEN($AG$25))),(ROW()-ROW($AH$25)+1)*LEN($AG$25),LEN($AG$25))) -> 철 | AI27: =IF(AH27<>"",VLOOKUP(AH27,$A$1:$B$130,2,FALSE),0) -> 32
D28: =TRIM(MID(SUBSTITUTE($C$25,"+",REPT(" ",LEN($C$25))),(ROW()-ROW($D$25)+1)*LEN($C$25),LEN($C$25))) | E28: =IF(D28<>"",VLOOKUP(D28,$A$1:$B$130,2,FALSE),0) -> 0 | I28: =TRIM(MID(SUBSTITUTE($H$25,"+",REPT(" ",LEN($H$25))),(ROW()-ROW($I$25)+1)*LEN($H$25),LEN($H$25))) | J28: =IF(I28<>"",VLOOKUP(I28,$A$1:$B$130,2,FALSE),0) -> 0 | N28: =TRIM(MID(SUBSTITUTE($M$25,"+",REPT(" ",LEN($M$25))),(ROW()-ROW($N$25)+1)*LEN($M$25),LEN($M$25))) | O28: =IF(N28<>"",VLOOKUP(N28,$A$1:$B$130,2,FALSE),0) -> 0 | S28: =TRIM(MID(SUBSTITUTE($R$25,"+",REPT(" ",LEN($R$25))),(ROW()-ROW($S$25)+1)*LEN($R$25),LEN($R$25))) -> 철 | T28: =IF(S28<>"",VLOOKUP(S28,$A$1:$B$130,2,FALSE),0) -> 32 | X28: =TRIM(MID(SUBSTITUTE($W$25,"+",REPT(" ",LEN($W$25))),(ROW()-ROW($X$25)+1)*LEN($W$25),LEN($W$25))) -> 천 | Y28: =IF(X28<>"",VLOOKUP(X28,$A$1:$B$130,2,FALSE),0) -> 80 | AC28: =TRIM(MID(SUBSTITUTE($AB$25,"+",REPT(" ",LEN($AB$25))),(ROW()-ROW($AC$25)+1)*LEN($AB$25),LEN($AB$25))) | AD28: =IF(AC28<>"",VLOOKUP(AC28,$A$1:$B$130,2,FALSE),0) -> 0 | AH28: =TRIM(MID(SUBSTITUTE($AG$25,"+",REPT(" ",LEN($AG$25))),(ROW()-ROW($AH$25)+1)*LEN($AG$25),LEN($AG$25))) | AI28: =IF(AH28<>"",VLOOKUP(AH28,$A$1:$B$130,2,FALSE),0) -> 0
D29: =TRIM(MID(SUBSTITUTE($C$25,"+",REPT(" ",LEN($C$25))),(ROW()-ROW($D$25)+1)*LEN($C$25),LEN($C$25))) | E29: =IF(D29<>"",VLOOKUP(D29,$A$1:$B$130,2,FALSE),0) -> 0 | I29: =TRIM(MID(SUBSTITUTE($H$25,"+",REPT(" ",LEN($H$25))),(ROW()-ROW($I$25)+1)*LEN($H$25),LEN($H$25))) | J29: =IF(I29<>"",VLOOKUP(I29,$A$1:$B$130,2,FALSE),0) -> 0 | N29: =TRIM(MID(SUBSTITUTE($M$25,"+",REPT(" ",LEN($M$25))),(ROW()-ROW($N$25)+1)*LEN($M$25),LEN($M$25))) | O29: =IF(N29<>"",VLOOKUP(N29,$A$1:$B$130,2,FALSE),0) -> 0 | S29: =TRIM(MID(SUBSTITUTE($R$25,"+",REPT(" ",LEN($R$25))),(ROW()-ROW($S$25)+1)*LEN($R$25),LEN($R$25))) -> 황동 | T29: =IF(S29<>"",VLOOKUP(S29,$A$1:$B$130,2,FALSE),0) -> 64 | X29: =TRIM(MID(SUBSTITUTE($W$25,"+",REPT(" ",LEN($W$25))),(ROW()-ROW($X$25)+1)*LEN($W$25),LEN($W$25))) | Y29: =IF(X29<>"",VLOOKUP(X29,$A$1:$B$130,2,FALSE),0) -> 0 | AC29: =TRIM(MID(SUBSTITUTE($AB$25,"+",REPT(" ",LEN($AB$25))),(ROW()-ROW($AC$25)+1)*LEN($AB$25),LEN($AB$25))) | AD29: =IF(AC29<>"",VLOOKUP(AC29,$A$1:$B$130,2,FALSE),0) -> 0 | AH29: =TRIM(MID(SUBSTITUTE($AG$25,"+",REPT(" ",LEN($AG$25))),(ROW()-ROW($AH$25)+1)*LEN($AG$25),LEN($AG$25))) | AI29: =IF(AH29<>"",VLOOKUP(AH29,$A$1:$B$130,2,FALSE),0) -> 0
D30: =TRIM(MID(SUBSTITUTE($C$25,"+",REPT(" ",LEN($C$25))),(ROW()-ROW($D$25)+1)*LEN($C$25),LEN($C$25))) | E30: =IF(D30<>"",VLOOKUP(D30,$A$1:$B$130,2,FALSE),0) -> 0 | I30: =TRIM(MID(SUBSTITUTE($H$25,"+",REPT(" ",LEN($H$25))),(ROW()-ROW($I$25)+1)*LEN($H$25),LEN($H$25))) | J30: =IF(I30<>"",VLOOKUP(I30,$A$1:$B$130,2,FALSE),0) -> 0 | N30: =TRIM(MID(SUBSTITUTE($M$25,"+",REPT(" ",LEN($M$25))),(ROW()-ROW($N$25)+1)*LEN($M$25),LEN($M$25))) | O30: =IF(N30<>"",VLOOKUP(N30,$A$1:$B$130,2,FALSE),0) -> 0 | S30: =TRIM(MID(SUBSTITUTE($R$25,"+",REPT(" ",LEN($R$25))),(ROW()-ROW($S$25)+1)*LEN($R$25),LEN($R$25))) | T30: =IF(S30<>"",VLOOKUP(S30,$A$1:$B$130,2,FALSE),0) -> 0 | X30: =TRIM(MID(SUBSTITUTE($W$25,"+",REPT(" ",LEN($W$25))),(ROW()-ROW($X$25)+1)*LEN($W$25),LEN($W$25))) | Y30: =IF(X30<>"",VLOOKUP(X30,$A$1:$B$130,2,FALSE),0) -> 0 | AC30: =TRIM(MID(SUBSTITUTE($AB$25,"+",REPT(" ",LEN($AB$25))),(ROW()-ROW($AC$25)+1)*LEN($AB$25),LEN($AB$25))) | AD30: =IF(AC30<>"",VLOOKUP(AC30,$A$1:$B$130,2,FALSE),0) -> 0 | AH30: =TRIM(MID(SUBSTITUTE($AG$25,"+",REPT(" ",LEN($AG$25))),(ROW()-ROW($AH$25)+1)*LEN($AG$25),LEN($AG$25))) | AI30: =IF(AH30<>"",VLOOKUP(AH30,$A$1:$B$130,2,FALSE),0) -> 0
D31: =TRIM(MID(SUBSTITUTE($C$25,"+",REPT(" ",LEN($C$25))),(ROW()-ROW($D$25)+1)*LEN($C$25),LEN($C$25))) | E31: =IF(D31<>"",VLOOKUP(D31,$A$1:$B$130,2,FALSE),0) -> 0 | I31: =TRIM(MID(SUBSTITUTE($H$25,"+",REPT(" ",LEN($H$25))),(ROW()-ROW($I$25)+1)*LEN($H$25),LEN($H$25))) | J31: =IF(I31<>"",VLOOKUP(I31,$A$1:$B$130,2,FALSE),0) -> 0 | N31: =TRIM(MID(SUBSTITUTE($M$25,"+",REPT(" ",LEN($M$25))),(ROW()-ROW($N$25)+1)*LEN($M$25),LEN($M$25))) | O31: =IF(N31<>"",VLOOKUP(N31,$A$1:$B$130,2,FALSE),0) -> 0 | S31: =TRIM(MID(SUBSTITUTE($R$25,"+",REPT(" ",LEN($R$25))),(ROW()-ROW($S$25)+1)*LEN($R$25),LEN($R$25))) | T31: =IF(S31<>"",VLOOKUP(S31,$A$1:$B$130,2,FALSE),0) -> 0 | X31: =TRIM(MID(SUBSTITUTE($W$25,"+",REPT(" ",LEN($W$25))),(ROW()-ROW($X$25)+1)*LEN($W$25),LEN($W$25))) | Y31: =IF(X31<>"",VLOOKUP(X31,$A$1:$B$130,2,FALSE),0) -> 0 | AC31: =TRIM(MID(SUBSTITUTE($AB$25,"+",REPT(" ",LEN($AB$25))),(ROW()-ROW($AC$25)+1)*LEN($AB$25),LEN($AB$25))) | AD31: =IF(AC31<>"",VLOOKUP(AC31,$A$1:$B$130,2,FALSE),0) -> 0 | AH31: =TRIM(MID(SUBSTITUTE($AG$25,"+",REPT(" ",LEN($AG$25))),(ROW()-ROW($AH$25)+1)*LEN($AG$25),LEN($AG$25))) | AI31: =IF(AH31<>"",VLOOKUP(AH31,$A$1:$B$130,2,FALSE),0) -> 0
D32: =TRIM(MID(SUBSTITUTE($C$25,"+",REPT(" ",LEN($C$25))),(ROW()-ROW($D$25)+1)*LEN($C$25),LEN($C$25))) | E32: =IF(D32<>"",VLOOKUP(D32,$A$1:$B$130,2,FALSE),0) -> 0 | I32: =TRIM(MID(SUBSTITUTE($H$25,"+",REPT(" ",LEN($H$25))),(ROW()-ROW($I$25)+1)*LEN($H$25),LEN($H$25))) | J32: =IF(I32<>"",VLOOKUP(I32,$A$1:$B$130,2,FALSE),0) -> 0 | N32: =TRIM(MID(SUBSTITUTE($M$25,"+",REPT(" ",LEN($M$25))),(ROW()-ROW($N$25)+1)*LEN($M$25),LEN($M$25))) | O32: =IF(N32<>"",VLOOKUP(N32,$A$1:$B$130,2,FALSE),0) -> 0 | S32: =TRIM(MID(SUBSTITUTE($R$25,"+",REPT(" ",LEN($R$25))),(ROW()-ROW($S$25)+1)*LEN($R$25),LEN($R$25))) | T32: =IF(S32<>"",VLOOKUP(S32,$A$1:$B$130,2,FALSE),0) -> 0 | X32: =TRIM(MID(SUBSTITUTE($W$25,"+",REPT(" ",LEN($W$25))),(ROW()-ROW($X$25)+1)*LEN($W$25),LEN($W$25))) | Y32: =IF(X32<>"",VLOOKUP(X32,$A$1:$B$130,2,FALSE),0) -> 0 | AC32: =TRIM(MID(SUBSTITUTE($AB$25,"+",REPT(" ",LEN($AB$25))),(ROW()-ROW($AC$25)+1)*LEN($AB$25),LEN($AB$25))) | AD32: =IF(AC32<>"",VLOOKUP(AC32,$A$1:$B$130,2,FALSE),0) -> 0 | AH32: =TRIM(MID(SUBSTITUTE($AG$25,"+",REPT(" ",LEN($AG$25))),(ROW()-ROW($AH$25)+1)*LEN($AG$25),LEN($AG$25))) | AI32: =IF(AH32<>"",VLOOKUP(AH32,$A$1:$B$130,2,FALSE),0) -> 0
D33: =TRIM(MID(SUBSTITUTE($C$25,"+",REPT(" ",LEN($C$25))),(ROW()-ROW($D$25)+1)*LEN($C$25),LEN($C$25))) | E33: =IF(D33<>"",VLOOKUP(D33,$A$1:$B$130,2,FALSE),0) -> 0 | I33: =TRIM(MID(SUBSTITUTE($H$25,"+",REPT(" ",LEN($H$25))),(ROW()-ROW($I$25)+1)*LEN($H$25),LEN($H$25))) | J33: =IF(I33<>"",VLOOKUP(I33,$A$1:$B$130,2,FALSE),0) -> 0 | N33: =TRIM(MID(SUBSTITUTE($M$25,"+",REPT(" ",LEN($M$25))),(ROW()-ROW($N$25)+1)*LEN($M$25),LEN($M$25))) | O33: =IF(N33<>"",VLOOKUP(N33,$A$1:$B$130,2,FALSE),0) -> 0 | S33: =TRIM(MID(SUBSTITUTE($R$25,"+",REPT(" ",LEN($R$25))),(ROW()-ROW($S$25)+1)*LEN($R$25),LEN($R$25))) | T33: =IF(S33<>"",VLOOKUP(S33,$A$1:$B$130,2,FALSE),0) -> 0 | X33: =TRIM(MID(SUBSTITUTE($W$25,"+",REPT(" ",LEN($W$25))),(ROW()-ROW($X$25)+1)*LEN($W$25),LEN($W$25))) | Y33: =IF(X33<>"",VLOOKUP(X33,$A$1:$B$130,2,FALSE),0) -> 0 | AC33: =TRIM(MID(SUBSTITUTE($AB$25,"+",REPT(" ",LEN($AB$25))),(ROW()-ROW($AC$25)+1)*LEN($AB$25),LEN($AB$25))) | AD33: =IF(AC33<>"",VLOOKUP(AC33,$A$1:$B$130,2,FALSE),0) -> 0 | AH33: =TRIM(MID(SUBSTITUTE($AG$25,"+",REPT(" ",LEN($AG$25))),(ROW()-ROW($AH$25)+1)*LEN($AG$25),LEN($AG$25))) | AI33: =IF(AH33<>"",VLOOKUP(AH33,$A$1:$B$130,2,FALSE),0) -> 0
D34: =TRIM(MID(SUBSTITUTE($C$25,"+",REPT(" ",LEN($C$13))),(ROW()-ROW($C$25)+1)*LEN($C$13),LEN($C$13))) | E34: =IF(D34<>"",VLOOKUP(D34,$A$1:$B$130,2,FALSE),0) -> 0 | I34: =TRIM(MID(SUBSTITUTE($H$25,"+",REPT(" ",LEN($C$13))),(ROW()-ROW($H$25)+1)*LEN($C$13),LEN($C$13))) | J34: =IF(I34<>"",VLOOKUP(I34,$A$1:$B$130,2,FALSE),0) -> 0 | N34: =TRIM(MID(SUBSTITUTE($M$25,"+",REPT(" ",LEN($M$25))),(ROW()-ROW($N$25)+1)*LEN($M$25),LEN($M$25))) | O34: =IF(N34<>"",VLOOKUP(N34,$A$1:$B$130,2,FALSE),0) -> 0 | S34: =TRIM(MID(SUBSTITUTE($R$25,"+",REPT(" ",LEN($R$25))),(ROW()-ROW($S$25)+1)*LEN($R$25),LEN($R$25))) | T34: =IF(S34<>"",VLOOKUP(S34,$A$1:$B$130,2,FALSE),0) -> 0 | X34: =TRIM(MID(SUBSTITUTE($W$25,"+",REPT(" ",LEN($W$25))),(ROW()-ROW($X$25)+1)*LEN($W$25),LEN($W$25))) | Y34: =IF(X34<>"",VLOOKUP(X34,$A$1:$B$130,2,FALSE),0) -> 0 | AC34: =TRIM(MID(SUBSTITUTE($AB$25,"+",REPT(" ",LEN($AB$25))),(ROW()-ROW($AC$25)+1)*LEN($AB$25),LEN($AB$25))) | AD34: =IF(AC34<>"",VLOOKUP(AC34,$A$1:$B$130,2,FALSE),0) -> 0 | AH34: =TRIM(MID(SUBSTITUTE($AG$25,"+",REPT(" ",LEN($AG$25))),(ROW()-ROW($AH$25)+1)*LEN($AG$25),LEN($AG$25))) | AI34: =IF(AH34<>"",VLOOKUP(AH34,$A$1:$B$130,2,FALSE),0) -> 0
C35: 15 | H35: 16 | M35: 17 | R35: 18 | W35: 19 | AB35: 20 | AG35: 21 | AL35: 22=총+총알
C37: =표!Y27 -> +단 열매+쓴 열매+작은 물고기+큰 물고기 | D37: =TRIM(MID(SUBSTITUTE($C$37,"+",REPT(" ",LEN($C$37))),(ROW()-ROW($D$37)+1)*LEN($C$37),LEN($C$37))) -> 단 열매 | E37: =IF(D37<>"",VLOOKUP(D37,$A$1:$B$130,2,FALSE),0) -> 16 | F37: =SUM(E37:E46) -> 80 | H37: =표!Y28 -> 단 열매+쓴 열매+산삼 | I37: =TRIM(MID(SUBSTITUTE($H$37,"+",REPT(" ",LEN($H$37))),(ROW()-ROW($I$37)+1)*LEN($H$37),LEN($H$37))) -> 쓴 열매 | J37: =IF(I37<>"",VLOOKUP(I37,$A$1:$B$130,2,FALSE),0) -> 16 | K37: =SUM(J37:J46) -> 116 | M37: =표!Y29 -> +작은 물고기+큰 물고기+철 | N37: =TRIM(MID(SUBSTITUTE($M$37,"+",REPT(" ",LEN($M$37))),(ROW()-ROW($N$37)+1)*LEN($M$37),LEN($M$37))) -> 작은 물고기 | O37: =IF(N37<>"",VLOOKUP(N37,$A$1:$B$130,2,FALSE),0) -> 16 | P37: =SUM(O37:O46) -> 80 | R37: =표!Y30 -> +상어+단 열매+철 | S37: =TRIM(MID(SUBSTITUTE($R$37,"+",REPT(" ",LEN($R$37))),(ROW()-ROW($S$37)+1)*LEN($R$37),LEN($R$37))) -> 상어 | T37: =IF(S37<>"",VLOOKUP(S37,$A$1:$B$130,2,FALSE),0) -> 100 | U37: =SUM(T37:T46) -> 148 | W37: =표!Y31 -> 0 | X37: =TRIM(MID(SUBSTITUTE($W$37,"+",REPT(" ",LEN($W$37))),(ROW()-ROW($X$37)+1)*LEN($W$37),LEN($W$37))) -> 0 | Y37: =IF(X37<>"",VLOOKUP(X37,$A$1:$B$130,2,FALSE),0) -> #N/A | Z37: =SUM(Y37:Y46) -> #N/A | AB37: =표!Y32 -> 0 | AC37: =TRIM(MID(SUBSTITUTE($AB$37,"+",REPT(" ",LEN($AB$37))),(ROW()-ROW($AC$37)+1)*LEN($AB$37),LEN($AB$37))) -> 0 | AD37: =IF(AC37<>"",VLOOKUP(AC37,$A$1:$B$130,2,FALSE),0) -> #N/A | AE37: =SUM(AD37:AD46) -> #N/A | AG37: =표!Y33 -> 0 | AH37: =TRIM(MID(SUBSTITUTE($AG$37,"+",REPT(" ",LEN($AG$37))),(ROW()-ROW($AH$37)+1)*LEN($AG$37),LEN($AG$37))) -> 0 | AI37: =IF(AH37<>"",VLOOKUP(AH37,$A$1:$B$130,2,FALSE),0) -> #N/A | AJ37: =SUM(AI37:AI46) -> #N/A
D38: =TRIM(MID(SUBSTITUTE($C$37,"+",REPT(" ",LEN($C$37))),(ROW()-ROW($D$37)+1)*LEN($C$37),LEN($C$37))) -> 쓴 열매 | E38: =IF(D38<>"",VLOOKUP(D38,$A$1:$B$130,2,FALSE),0) -> 16 | I38: =TRIM(MID(SUBSTITUTE($H$37,"+",REPT(" ",LEN($H$37))),(ROW()-ROW($I$37)+1)*LEN($H$37),LEN($H$37))) -> 산삼 | J38: =IF(I38<>"",VLOOKUP(I38,$A$1:$B$130,2,FALSE),0) -> 100 | N38: =TRIM(MID(SUBSTITUTE($M$37,"+",REPT(" ",LEN($M$37))),(ROW()-ROW($N$37)+1)*LEN($M$37),LEN($M$37))) -> 큰 물고기 | O38: =IF(N38<>"",VLOOKUP(N38,$A$1:$B$130,2,FALSE),0) -> 32 | S38: =TRIM(MID(SUBSTITUTE($R$37,"+",REPT(" ",LEN($R$37))),(ROW()-ROW($S$37)+1)*LEN($R$37),LEN($R$37))) -> 단 열매 | T38: =IF(S38<>"",VLOOKUP(S38,$A$1:$B$130,2,FALSE),0) -> 16 | X38: =TRIM(MID(SUBSTITUTE($W$37,"+",REPT(" ",LEN($W$37))),(ROW()-ROW($X$37)+1)*LEN($W$37),LEN($W$37))) | Y38: =IF(X38<>"",VLOOKUP(X38,$A$1:$B$130,2,FALSE),0) -> 0 | AC38: =TRIM(MID(SUBSTITUTE($AB$37,"+",REPT(" ",LEN($AB$37))),(ROW()-ROW($AC$37)+1)*LEN($AB$37),LEN($AB$37))) | AD38: =IF(AC38<>"",VLOOKUP(AC38,$A$1:$B$130,2,FALSE),0) -> 0 | AH38: =TRIM(MID(SUBSTITUTE($AG$37,"+",REPT(" ",LEN($AG$37))),(ROW()-ROW($AH$37)+1)*LEN($AG$37),LEN($AG$37))) | AI38: =IF(AH38<>"",VLOOKUP(AH38,$A$1:$B$130,2,FALSE),0) -> 0
D39: =TRIM(MID(SUBSTITUTE($C$37,"+",REPT(" ",LEN($C$37))),(ROW()-ROW($D$37)+1)*LEN($C$37),LEN($C$37))) -> 작은 물고기 | E39: =IF(D39<>"",VLOOKUP(D39,$A$1:$B$130,2,FALSE),0) -> 16 | I39: =TRIM(MID(SUBSTITUTE($H$37,"+",REPT(" ",LEN($H$37))),(ROW()-ROW($I$37)+1)*LEN($H$37),LEN($H$37))) | J39: =IF(I39<>"",VLOOKUP(I39,$A$1:$B$130,2,FALSE),0) -> 0 | N39: =TRIM(MID(SUBSTITUTE($M$37,"+",REPT(" ",LEN($M$37))),(ROW()-ROW($N$37)+1)*LEN($M$37),LEN($M$37))) -> 철 | O39: =IF(N39<>"",VLOOKUP(N39,$A$1:$B$130,2,FALSE),0) -> 32 | S39: =TRIM(MID(SUBSTITUTE($R$37,"+",REPT(" ",LEN($R$37))),(ROW()-ROW($S$37)+1)*LEN($R$37),LEN($R$37))) -> 철 | T39: =IF(S39<>"",VLOOKUP(S39,$A$1:$B$130,2,FALSE),0) -> 32 | X39: =TRIM(MID(SUBSTITUTE($W$37,"+",REPT(" ",LEN($W$37))),(ROW()-ROW($X$37)+1)*LEN($W$37),LEN($W$37))) | Y39: =IF(X39<>"",VLOOKUP(X39,$A$1:$B$130,2,FALSE),0) -> 0 | AC39: =TRIM(MID(SUBSTITUTE($AB$37,"+",REPT(" ",LEN($AB$37))),(ROW()-ROW($AC$37)+1)*LEN($AB$37),LEN($AB$37))) | AD39: =IF(AC39<>"",VLOOKUP(AC39,$A$1:$B$130,2,FALSE),0) -> 0 | AH39: =TRIM(MID(SUBSTITUTE($AG$37,"+",REPT(" ",LEN($AG$37))),(ROW()-ROW($AH$37)+1)*LEN($AG$37),LEN($AG$37))) | AI39: =IF(AH39<>"",VLOOKUP(AH39,$A$1:$B$130,2,FALSE),0) -> 0
D40: =TRIM(MID(SUBSTITUTE($C$37,"+",REPT(" ",LEN($C$37))),(ROW()-ROW($D$37)+1)*LEN($C$37),LEN($C$37))) -> 큰 물고기 | E40: =IF(D40<>"",VLOOKUP(D40,$A$1:$B$130,2,FALSE),0) -> 32 | I40: =TRIM(MID(SUBSTITUTE($H$37,"+",REPT(" ",LEN($H$37))),(ROW()-ROW($I$37)+1)*LEN($H$37),LEN($H$37))) | J40: =IF(I40<>"",VLOOKUP(I40,$A$1:$B$130,2,FALSE),0) -> 0 | N40: =TRIM(MID(SUBSTITUTE($M$37,"+",REPT(" ",LEN($M$37))),(ROW()-ROW($N$37)+1)*LEN($M$37),LEN($M$37))) | O40: =IF(N40<>"",VLOOKUP(N40,$A$1:$B$130,2,FALSE),0) -> 0 | S40: =TRIM(MID(SUBSTITUTE($R$37,"+",REPT(" ",LEN($R$37))),(ROW()-ROW($S$37)+1)*LEN($R$37),LEN($R$37))) | T40: =IF(S40<>"",VLOOKUP(S40,$A$1:$B$130,2,FALSE),0) -> 0 | X40: =TRIM(MID(SUBSTITUTE($W$37,"+",REPT(" ",LEN($W$37))),(ROW()-ROW($X$37)+1)*LEN($W$37),LEN($W$37))) | Y40: =IF(X40<>"",VLOOKUP(X40,$A$1:$B$130,2,FALSE),0) -> 0 | AC40: =TRIM(MID(SUBSTITUTE($AB$37,"+",REPT(" ",LEN($AB$37))),(ROW()-ROW($AC$37)+1)*LEN($AB$37),LEN($AB$37))) | AD40: =IF(AC40<>"",VLOOKUP(AC40,$A$1:$B$130,2,FALSE),0) -> 0 | AH40: =TRIM(MID(SUBSTITUTE($AG$37,"+",REPT(" ",LEN($AG$37))),(ROW()-ROW($AH$37)+1)*LEN($AG$37),LEN($AG$37))) | AI40: =IF(AH40<>"",VLOOKUP(AH40,$A$1:$B$130,2,FALSE),0) -> 0
D41: =TRIM(MID(SUBSTITUTE($C$37,"+",REPT(" ",LEN($C$37))),(ROW()-ROW($D$37)+1)*LEN($C$37),LEN($C$37))) | E41: =IF(D41<>"",VLOOKUP(D41,$A$1:$B$130,2,FALSE),0) -> 0 | I41: =TRIM(MID(SUBSTITUTE($H$37,"+",REPT(" ",LEN($H$37))),(ROW()-ROW($I$37)+1)*LEN($H$37),LEN($H$37))) | J41: =IF(I41<>"",VLOOKUP(I41,$A$1:$B$130,2,FALSE),0) -> 0 | N41: =TRIM(MID(SUBSTITUTE($M$37,"+",REPT(" ",LEN($M$37))),(ROW()-ROW($N$37)+1)*LEN($M$37),LEN($M$37))) | O41: =IF(N41<>"",VLOOKUP(N41,$A$1:$B$130,2,FALSE),0) -> 0 | S41: =TRIM(MID(SUBSTITUTE($R$37,"+",REPT(" ",LEN($R$37))),(ROW()-ROW($S$37)+1)*LEN($R$37),LEN($R$37))) | T41: =IF(S41<>"",VLOOKUP(S41,$A$1:$B$130,2,FALSE),0) -> 0 | X41: =TRIM(MID(SUBSTITUTE($W$37,"+",REPT(" ",LEN($W$37))),(ROW()-ROW($X$37)+1)*LEN($W$37),LEN($W$37))) | Y41: =IF(X41<>"",VLOOKUP(X41,$A$1:$B$130,2,FALSE),0) -> 0 | AC41: =TRIM(MID(SUBSTITUTE($AB$37,"+",REPT(" ",LEN($AB$37))),(ROW()-ROW($AC$37)+1)*LEN($AB$37),LEN($AB$37))) | AD41: =IF(AC41<>"",VLOOKUP(AC41,$A$1:$B$130,2,FALSE),0) -> 0 | AH41: =TRIM(MID(SUBSTITUTE($AG$37,"+",REPT(" ",LEN($AG$37))),(ROW()-ROW($AH$37)+1)*LEN($AG$37),LEN($AG$37))) | AI41: =IF(AH41<>"",VLOOKUP(AH41,$A$1:$B$130,2,FALSE),0) -> 0
...
